<?xml version="1.0" ?>
<sdf version="1.6">
  <model name="raspbot">
    <!-- Spawn pose is handled by ros_gz_sim create (-x/-y/-z) -->

    <link name="chassis">
      <pose>0 0 0.04 0 0 0</pose>
      <inertial>
        <mass>2.0</mass>
        <inertia>
          <ixx>0.02</ixx><ixy>0</ixy><ixz>0</ixz>
          <iyy>0.03</iyy><iyz>0</iyz>
          <izz>0.04</izz>
        </inertia>
      </inertial>
      <visual name="visual">
        <geometry>
          <box><size>0.32 0.22 0.08</size></box>
        </geometry>
        <material>
          <ambient>0.7 0.7 0.7 1</ambient>
          <diffuse>0.7 0.7 0.7 1</diffuse>
        </material>
      </visual>
      <collision name="collision">
        <geometry>
          <box><size>0.32 0.22 0.08</size></box>
        </geometry>
      </collision>
    </link>

    <!-- Wheels: cylinders rotated so axis is along Y -->
    <link name="front_left_wheel">
      <pose>0.11 0.09 0.05 0 1.5707 0</pose>
      <inertial>
        <mass>0.2</mass>
        <inertia>
          <ixx>0.0002</ixx><ixy>0</ixy><ixz>0</ixz>
          <iyy>0.0002</iyy><iyz>0</iyz>
          <izz>0.0002</izz>
        </inertia>
      </inertial>
      <visual name="visual">
        <geometry><cylinder><radius>0.05</radius><length>0.02</length></cylinder></geometry>
        <material><ambient>0.1 0.1 0.1 1</ambient><diffuse>0.1 0.1 0.1 1</diffuse></material>
      </visual>
      <collision name="collision">
        <geometry><cylinder><radius>0.05</radius><length>0.02</length></cylinder></geometry>
        <surface>
          <friction>
            <ode>
              <mu>1</mu><mu2>1</mu2>
              <slip1>0.035</slip1><slip2>0</slip2>
              <fdir1>0 0 1</fdir1>
            </ode>
          </friction>
        </surface>
      </collision>
    </link>

    <link name="rear_left_wheel">
      <pose>-0.11 0.09 0.05 0 1.5707 0</pose>
      <inertial>
        <mass>0.2</mass>
        <inertia>
          <ixx>0.0002</ixx><ixy>0</ixy><ixz>0</ixz>
          <iyy>0.0002</iyy><iyz>0</iyz>
          <izz>0.0002</izz>
        </inertia>
      </inertial>
      <visual name="visual">
        <geometry><cylinder><radius>0.05</radius><length>0.02</length></cylinder></geometry>
        <material><ambient>0.1 0.1 0.1 1</ambient><diffuse>0.1 0.1 0.1 1</diffuse></material>
      </visual>
      <collision name="collision">
        <geometry><cylinder><radius>0.05</radius><length>0.02</length></cylinder></geometry>
        <surface>
          <friction>
            <ode>
              <mu>1</mu><mu2>1</mu2>
              <slip1>0.035</slip1><slip2>0</slip2>
              <fdir1>0 0 1</fdir1>
            </ode>
          </friction>
        </surface>
      </collision>
    </link>

    <link name="front_right_wheel">
      <pose>0.11 -0.09 0.05 0 1.5707 0</pose>
      <inertial>
        <mass>0.2</mass>
        <inertia>
          <ixx>0.0002</ixx><ixy>0</ixy><ixz>0</ixz>
          <iyy>0.0002</iyy><iyz>0</iyz>
          <izz>0.0002</izz>
        </inertia>
      </inertial>
      <visual name="visual">
        <geometry><cylinder><radius>0.05</radius><length>0.02</length></cylinder></geometry>
        <material><ambient>0.1 0.1 0.1 1</ambient><diffuse>0.1 0.1 0.1 1</diffuse></material>
      </visual>
      <collision name="collision">
        <geometry><cylinder><radius>0.05</radius><length>0.02</length></cylinder></geometry>
        <surface>
          <friction>
            <ode>
              <mu>1</mu><mu2>1</mu2>
              <slip1>0.035</slip1><slip2>0</slip2>
              <fdir1>0 0 1</fdir1>
            </ode>
          </friction>
        </surface>
      </collision>
    </link>

    <link name="rear_right_wheel">
      <pose>-0.11 -0.09 0.05 0 1.5707 0</pose>
      <inertial>
        <mass>0.2</mass>
        <inertia>
          <ixx>0.0002</ixx><ixy>0</ixy><ixz>0</ixz>
          <iyy>0.0002</iyy><iyz>0</iyz>
          <izz>0.0002</izz>
        </inertia>
      </inertial>
      <visual name="visual">
        <geometry><cylinder><radius>0.05</radius><length>0.02</length></cylinder></geometry>
        <material><ambient>0.1 0.1 0.1 1</ambient><diffuse>0.1 0.1 0.1 1</diffuse></material>
      </visual>
      <collision name="collision">
        <geometry><cylinder><radius>0.05</radius><length>0.02</length></cylinder></geometry>
        <surface>
          <friction>
            <ode>
              <mu>1</mu><mu2>1</mu2>
              <slip1>0.035</slip1><slip2>0</slip2>
              <fdir1>0 0 1</fdir1>
            </ode>
          </friction>
        </surface>
      </collision>
    </link>

    <joint name="front_left_wheel_joint" type="revolute">
      <parent>chassis</parent>
      <child>front_left_wheel</child>
      <axis>
        <xyz>0 1 0</xyz>
        <limit><lower>-1.79769e+308</lower><upper>1.79769e+308</upper></limit>
      </axis>
    </joint>
    <joint name="rear_left_wheel_joint" type="revolute">
      <parent>chassis</parent>
      <child>rear_left_wheel</child>
      <axis>
        <xyz>0 1 0</xyz>
        <limit><lower>-1.79769e+308</lower><upper>1.79769e+308</upper></limit>
      </axis>
    </joint>
    <joint name="front_right_wheel_joint" type="revolute">
      <parent>chassis</parent>
      <child>front_right_wheel</child>
      <axis>
        <xyz>0 1 0</xyz>
        <limit><lower>-1.79769e+308</lower><upper>1.79769e+308</upper></limit>
      </axis>
    </joint>
    <joint name="rear_right_wheel_joint" type="revolute">
      <parent>chassis</parent>
      <child>rear_right_wheel</child>
      <axis>
        <xyz>0 1 0</xyz>
        <limit><lower>-1.79769e+308</lower><upper>1.79769e+308</upper></limit>
      </axis>
    </joint>

    <plugin filename="ignition-gazebo-diff-drive-system" name="gz::sim::systems::DiffDrive">
      <left_joint>front_left_wheel_joint</left_joint>
      <left_joint>rear_left_wheel_joint</left_joint>
      <right_joint>front_right_wheel_joint</right_joint>
      <right_joint>rear_right_wheel_joint</right_joint>
      <wheel_separation>0.18</wheel_separation>
      <wheel_radius>0.05</wheel_radius>
      <max_linear_velocity>0.6</max_linear_velocity>
      <max_angular_velocity>2.0</max_angular_velocity>
    </plugin>
  </model>
</sdf>

